{
  "Header": {
    "Original": "CVE-2019-9740 (An issue was discovered in urllib2 in Python 2.x through 2.7.16 and ur ...)",
    "Line": 293756,
    "ID": "CVE-2019-9740",
    "Description": "(An issue was discovered in urllib2 in Python 2.x through 2.7.16 and ur ...)"
  },
  "Annotations": [
    {
      "Original": "{DLA-2337-1 DLA-2280-1 DLA-1835-1 DLA-1834-1}",
      "Line": 293757,
      "Type": "xref",
      "Bugs": [
        "DLA-2337-1",
        "DLA-2280-1",
        "DLA-1835-1",
        "DLA-1834-1"
      ]
    },
    {
      "Original": "- python3.7 3.7.4~rc2-2",
      "Line": 293758,
      "Type": "package",
      "Package": "python3.7",
      "Kind": "fixed",
      "Version": "3.7.4~rc2-2"
    },
    {
      "Original": "[buster] - python3.7 3.7.3-2+deb10u1",
      "Line": 293759,
      "Type": "package",
      "Release": "buster",
      "Package": "python3.7",
      "Kind": "fixed",
      "Version": "3.7.3-2+deb10u1"
    },
    {
      "Original": "- python3.6 \u003cremoved\u003e",
      "Line": 293760,
      "Type": "package",
      "Package": "python3.6",
      "Kind": "removed"
    },
    {
      "Original": "- python3.5 \u003cremoved\u003e",
      "Line": 293761,
      "Type": "package",
      "Package": "python3.5",
      "Kind": "removed"
    },
    {
      "Original": "- python3.4 \u003cremoved\u003e",
      "Line": 293762,
      "Type": "package",
      "Package": "python3.4",
      "Kind": "removed"
    },
    {
      "Original": "- python2.7 2.7.16-3",
      "Line": 293763,
      "Type": "package",
      "Package": "python2.7",
      "Kind": "fixed",
      "Version": "2.7.16-3"
    },
    {
      "Original": "[buster] - python2.7 2.7.16-2+deb10u1",
      "Line": 293764,
      "Type": "package",
      "Release": "buster",
      "Package": "python2.7",
      "Kind": "fixed",
      "Version": "2.7.16-2+deb10u1"
    },
    {
      "Original": "NOTE: https://bugs.python.org/issue30458",
      "Line": 293765,
      "Type": "NOTE",
      "Description": "https://bugs.python.org/issue30458"
    },
    {
      "Original": "NOTE: https://bugs.python.org/issue36276 (duplicate)",
      "Line": 293766,
      "Type": "NOTE",
      "Description": "https://bugs.python.org/issue36276 (duplicate)"
    },
    {
      "Original": "NOTE: https://bugs.python.org/issue36274 (common regression fix)",
      "Line": 293767,
      "Type": "NOTE",
      "Description": "https://bugs.python.org/issue36274 (common regression fix)"
    },
    {
      "Original": "NOTE: https://bugs.python.org/issue38216 (common regression fix)",
      "Line": 293768,
      "Type": "NOTE",
      "Description": "https://bugs.python.org/issue38216 (common regression fix)"
    },
    {
      "Original": "NOTE: CVE-2019-9947 issue fixed with same fix as for CVE-2019-9740",
      "Line": 293769,
      "Type": "NOTE",
      "Description": "CVE-2019-9947 issue fixed with same fix as for CVE-2019-9740"
    },
    {
      "Original": "NOTE: Patch 2.7: https://github.com/python/cpython/commit/bb8071a4cae5ab3fe321481dd3d73662ffb26052",
      "Line": 293770,
      "Type": "NOTE",
      "Description": "Patch 2.7: https://github.com/python/cpython/commit/bb8071a4cae5ab3fe321481dd3d73662ffb26052"
    }
  ]
}