{
  "Header": {
    "Original": "CVE-2018-6594 (lib/Crypto/PublicKey/ElGamal.py in PyCrypto through 2.6.1 generates we ...)",
    "Line": 353931,
    "ID": "CVE-2018-6594",
    "Description": "(lib/Crypto/PublicKey/ElGamal.py in PyCrypto through 2.6.1 generates we ...)"
  },
  "Annotations": [
    {
      "Original": "- pycryptodome 3.4.11-1 (bug #889998)",
      "Line": 353932,
      "Type": "package",
      "Package": "pycryptodome",
      "Kind": "fixed",
      "Version": "3.4.11-1",
      "BugNo": 889998
    },
    {
      "Original": "- python-crypto 2.6.1-9 (bug #889999)",
      "Line": 353933,
      "Type": "package",
      "Package": "python-crypto",
      "Kind": "fixed",
      "Version": "2.6.1-9",
      "BugNo": 889999
    },
    {
      "Original": "[stretch] - python-crypto \u003cno-dsa\u003e (Minor issue)",
      "Line": 353934,
      "Type": "package",
      "Release": "stretch",
      "Package": "python-crypto",
      "Kind": "no-dsa",
      "Description": "Minor issue"
    },
    {
      "Original": "[jessie] - python-crypto \u003cno-dsa\u003e (Minor issue)",
      "Line": 353935,
      "Type": "package",
      "Release": "jessie",
      "Package": "python-crypto",
      "Kind": "no-dsa",
      "Description": "Minor issue"
    },
    {
      "Original": "[wheezy] - python-crypto \u003cno-dsa\u003e (Minor issue)",
      "Line": 353936,
      "Type": "package",
      "Release": "wheezy",
      "Package": "python-crypto",
      "Kind": "no-dsa",
      "Description": "Minor issue"
    },
    {
      "Original": "NOTE: PyCrypto: https://github.com/dlitz/pycrypto/issues/253",
      "Line": 353937,
      "Type": "NOTE",
      "Description": "PyCrypto: https://github.com/dlitz/pycrypto/issues/253"
    },
    {
      "Original": "NOTE: The issue is found as well in pycryptodome (fork from python-crypto)",
      "Line": 353938,
      "Type": "NOTE",
      "Description": "The issue is found as well in pycryptodome (fork from python-crypto)"
    },
    {
      "Original": "NOTE: PyCryptodome: https://github.com/Legrandin/pycryptodome/issues/90",
      "Line": 353939,
      "Type": "NOTE",
      "Description": "PyCryptodome: https://github.com/Legrandin/pycryptodome/issues/90"
    },
    {
      "Original": "NOTE: PyCrytpodome: https://github.com/Legrandin/pycryptodome/commit/99c27a3b9e8a884bbde0e88c63234b669d4398d8 (3.4.10)",
      "Line": 353940,
      "Type": "NOTE",
      "Description": "PyCrytpodome: https://github.com/Legrandin/pycryptodome/commit/99c27a3b9e8a884bbde0e88c63234b669d4398d8 (3.4.10)"
    },
    {
      "Original": "NOTE: See further discussion as per https://github.com/Legrandin/pycryptodome/issues/90#issuecomment-362783537",
      "Line": 353941,
      "Type": "NOTE",
      "Description": "See further discussion as per https://github.com/Legrandin/pycryptodome/issues/90#issuecomment-362783537"
    },
    {
      "Original": "NOTE: Upstream feels that this is not a vulnerability in pycryptodome/python-crypto,",
      "Line": 353942,
      "Type": "NOTE",
      "Description": "Upstream feels that this is not a vulnerability in pycryptodome/python-crypto,"
    },
    {
      "Original": "NOTE: but in an application using it in an insecure manner.",
      "Line": 353943,
      "Type": "NOTE",
      "Description": "but in an application using it in an insecure manner."
    }
  ]
}