{
  "Header": {
    "Original": "CVE-2019-13611 (An issue was discovered in python-engineio through 3.8.2. There is a C ...)",
    "Line": 284249,
    "ID": "CVE-2019-13611",
    "Description": "(An issue was discovered in python-engineio through 3.8.2. There is a C ...)"
  },
  "Annotations": [
    {
      "Original": "- python-engineio 3.11.1-1 (bug #932538)",
      "Line": 284250,
      "Type": "package",
      "Package": "python-engineio",
      "Kind": "fixed",
      "Version": "3.11.1-1",
      "BugNo": 932538
    },
    {
      "Original": "[buster] - python-engineio \u003cno-dsa\u003e (Minor issue)",
      "Line": 284251,
      "Type": "package",
      "Release": "buster",
      "Package": "python-engineio",
      "Kind": "no-dsa",
      "Description": "Minor issue"
    },
    {
      "Original": "NOTE: https://github.com/miguelgrinberg/python-engineio/issues/128",
      "Line": 284252,
      "Type": "NOTE",
      "Description": "https://github.com/miguelgrinberg/python-engineio/issues/128"
    },
    {
      "Original": "NOTE: https://github.com/miguelgrinberg/python-engineio/security/advisories/GHSA-j3jp-gvr5-7hwq",
      "Line": 284253,
      "Type": "NOTE",
      "Description": "https://github.com/miguelgrinberg/python-engineio/security/advisories/GHSA-j3jp-gvr5-7hwq"
    }
  ]
}