{
  "Header": {
    "Original": "CVE-2022-0718 (A flaw was found in python-oslo-utils. Due to improper parsing, passwo ...)",
    "Line": 95419,
    "ID": "CVE-2022-0718",
    "Description": "(A flaw was found in python-oslo-utils. Due to improper parsing, passwo ...)"
  },
  "Annotations": [
    {
      "Original": "{DLA-3106-1}",
      "Line": 95420,
      "Type": "xref",
      "Bugs": [
        "DLA-3106-1"
      ]
    },
    {
      "Original": "- python-oslo.utils 4.10.1-1",
      "Line": 95421,
      "Type": "package",
      "Package": "python-oslo.utils",
      "Kind": "fixed",
      "Version": "4.10.1-1"
    },
    {
      "Original": "[bullseye] - python-oslo.utils \u003cno-dsa\u003e (Minor issue)",
      "Line": 95422,
      "Type": "package",
      "Release": "bullseye",
      "Package": "python-oslo.utils",
      "Kind": "no-dsa",
      "Description": "Minor issue"
    },
    {
      "Original": "NOTE: https://bugzilla.redhat.com/show_bug.cgi?id=2056850",
      "Line": 95423,
      "Type": "NOTE",
      "Description": "https://bugzilla.redhat.com/show_bug.cgi?id=2056850"
    },
    {
      "Original": "NOTE: https://bugs.launchpad.net/oslo.utils/+bug/1949623",
      "Line": 95424,
      "Type": "NOTE",
      "Description": "https://bugs.launchpad.net/oslo.utils/+bug/1949623"
    },
    {
      "Original": "NOTE: Fixed by: https://opendev.org/openstack/oslo.utils/commit/6e17ae1f7959c64dfd20a5f67edf422e702426aa (4.12.1)",
      "Line": 95425,
      "Type": "NOTE",
      "Description": "Fixed by: https://opendev.org/openstack/oslo.utils/commit/6e17ae1f7959c64dfd20a5f67edf422e702426aa (4.12.1)"
    },
    {
      "Original": "NOTE: Fixed by: https://opendev.org/openstack/oslo.utils/commit/5ce8a7f0f8ecec7a85a23ec3d7a7fb1cad14ceba (4.10.1)",
      "Line": 95426,
      "Type": "NOTE",
      "Description": "Fixed by: https://opendev.org/openstack/oslo.utils/commit/5ce8a7f0f8ecec7a85a23ec3d7a7fb1cad14ceba (4.10.1)"
    }
  ]
}