{
  "Header": {
    "Original": "CVE-2019-16228 (An issue was discovered in py-lmdb 0.97. There is a divide-by-zero err ...)",
    "Line": 274966,
    "ID": "CVE-2019-16228",
    "Description": "(An issue was discovered in py-lmdb 0.97. There is a divide-by-zero err ...)"
  },
  "Annotations": [
    {
      "Original": "- py-lmdb \u003cunfixed\u003e (unimportant)",
      "Line": 274967,
      "Type": "package",
      "Package": "py-lmdb",
      "Kind": "unfixed",
      "Severity": "unimportant"
    },
    {
      "Original": "NOTE: https://github.com/jnwatson/py-lmdb/issues/210",
      "Line": 274968,
      "Type": "NOTE",
      "Description": "https://github.com/jnwatson/py-lmdb/issues/210"
    },
    {
      "Original": "NOTE: No real security issue in py-lmdb and disputed (MITRE contacted). If at all",
      "Line": 274969,
      "Type": "NOTE",
      "Description": "No real security issue in py-lmdb and disputed (MITRE contacted). If at all"
    },
    {
      "Original": "NOTE: then issues in underlying library but cf. https://github.com/jnwatson/py-lmdb/issues/210#issuecomment-531015023",
      "Line": 274970,
      "Type": "NOTE",
      "Description": "then issues in underlying library but cf. https://github.com/jnwatson/py-lmdb/issues/210#issuecomment-531015023"
    }
  ]
}