{
  "Header": {
    "Original": "CVE-2020-13401 (An issue was discovered in Docker Engine before 19.03.11. An attacker  ...)",
    "Line": 226312,
    "ID": "CVE-2020-13401",
    "Description": "(An issue was discovered in Docker Engine before 19.03.11. An attacker  ...)"
  },
  "Annotations": [
    {
      "Original": "{DSA-4716-1}",
      "Line": 226313,
      "Type": "xref",
      "Bugs": [
        "DSA-4716-1"
      ]
    },
    {
      "Original": "- docker.io 19.03.11+dfsg1-1 (bug #962141)",
      "Line": 226314,
      "Type": "package",
      "Package": "docker.io",
      "Kind": "fixed",
      "Version": "19.03.11+dfsg1-1",
      "BugNo": 962141
    },
    {
      "Original": "NOTE: https://bugzilla.redhat.com/show_bug.cgi?id=1833233",
      "Line": 226315,
      "Type": "NOTE",
      "Description": "https://bugzilla.redhat.com/show_bug.cgi?id=1833233"
    },
    {
      "Original": "NOTE: https://github.com/moby/libnetwork/commit/153d0769a1181bf591a9637fd487a541ec7db1e6",
      "Line": 226316,
      "Type": "NOTE",
      "Description": "https://github.com/moby/libnetwork/commit/153d0769a1181bf591a9637fd487a541ec7db1e6"
    }
  ]
}